Workbook
Name Additional_Instance: 'Static Reference Tables'!$H$11:$H$13
Name administrator_vsphere_local_password: 'Value Reference Tables'!$L$14
Name air_GPU_network_operator_namespace: 'Value Reference Tables'!$U$43
Name air_GPU_operator_namespace: 'Value Reference Tables'!$U$42
Name air_GPU_VM_class: 'Value Reference Tables'!$U$41
Name air_license: 'Value Reference Tables'!$U$40
Name asn_instance: 'Value Reference Tables - MR'!$AH$18
Name asn_mgmt_az1: 'Value Reference Tables - MR'!$AH$19
Name asn_mgmt_az2: 'Value Reference Tables - MR'!$AH$20
Name asn_start: 'Value Reference Tables - MR'!$AH$17
Name asn_wld_az1: 'Value Reference Tables - MR'!$AH$21
Name asn_wld_az2: 'Value Reference Tables - MR'!$AH$22
Name avilb_root_password: 'Value Reference Tables'!$L$32
Name aws_regions: 'Static Reference Tables'!$B$386:$B$413
Name ca_administrator_password: 'Value Reference Tables'!$L$31
Name ca_administrator_username: 'Value Reference Tables'!$L$8
Name ca_algorithm: 'Value Reference Tables'!$O$39
Name ca_country: 'Value Reference Tables'!$O$38
Name ca_email_address: 'Value Reference Tables'!$O$41
Name ca_key_size: 'Value Reference Tables'!$O$40
Name ca_locality: 'Value Reference Tables'!$O$42
Name ca_organization: 'Value Reference Tables'!$O$43
Name ca_organization_unit: 'Value Reference Tables'!$O$44
Name ca_state: 'Value Reference Tables'!$O$45
Name ca_template_name: 'Value Reference Tables'!$O$37
Name calculated_mgmt_host_count: #REF!
Name cbr_aria_logs_key: 'Value Reference Tables'!$U$149
Name cbr_aria_logs_url: 'Value Reference Tables'!$U$148
Name cbr_firewall_rule_vcenter: 'Value Reference Tables'!$U$134
Name cbr_recovery_host_count: 'Value Reference Tables'!$U$130
Name cbr_recovery_host_type: 'Value Reference Tables'!$U$129
Name cbr_recovery_management_subnet: 'Value Reference Tables'!$U$133
Name cbr_recovery_region: 'Value Reference Tables'!$U$128
Name cbr_recovery_sddc_name: 'Value Reference Tables'!$U$127
Name cbr_recovery_subnet: 'Value Reference Tables'!$U$132
Name cbr_recovery_vpc: 'Value Reference Tables'!$U$131
Name cbr_vcdr_anti_affinity: 'Value Reference Tables'!$U$145
Name cbr_vcdr_cdp1_hostname: 'Value Reference Tables'!$U$137
Name cbr_vcdr_cdp1_ip: 'Value Reference Tables'!$U$138
Name cbr_vcdr_cdp2_hostname: 'Value Reference Tables'!$U$139
Name cbr_vcdr_cdp2_ip: 'Value Reference Tables'!$U$140
Name cbr_vcdr_email_recipient: 'Value Reference Tables'!$U$146
Name cbr_vcdr_email_sender: 'Value Reference Tables'!$U$147
Name cbr_vcdr_label: 'Value Reference Tables'!$U$144
Name cbr_vcdr_orchestrator_fqdn: 'Value Reference Tables'!$U$142
Name cbr_vcdr_ova: 'Value Reference Tables'!$U$141
Name cbr_vcdr_passcode: 'Value Reference Tables'!$U$143
Name cbr_vcdr_site_name: 'Value Reference Tables'!$U$135
Name cbr_vcdr_timezone: 'Value Reference Tables'!$U$136
Name cbr_vcdr_vsphere_role: 'Value Reference Tables'!$U$123
Name cbr_vm_folder: 'Value Reference Tables'!$U$126
Name ccm_aws_admin_password: 'Value Reference Tables'!$U$180
Name ccm_aws_admin_ssouser: 'Value Reference Tables'!$U$179
Name ccm_aws_host_count: 'Value Reference Tables'!$U$164
Name ccm_aws_host_type: 'Value Reference Tables'!$U$163
Name ccm_aws_management_subnet: 'Value Reference Tables'!$U$167
Name ccm_aws_region: 'Value Reference Tables'!$U$162
Name ccm_aws_sddc_name: 'Value Reference Tables'!$U$161
Name ccm_aws_subnet: 'Value Reference Tables'!$U$166
Name ccm_aws_vpc: 'Value Reference Tables'!$U$165

Sheet CPUs
A1: CPU Series | B1: Cores/Threads | C1: CPUID Info | D1: CPUIDs | E1: Supported Releases
A2: AMD EPYC 7001 Series | B2: 32c/64t | C2: 17.01 | D2: 0x00800F10 | E2: ESXi 9.1
A3: AMD EPYC 7002/7Fx2/7Hx2 Series | B3: 64c/128t | C3: 17.31 | D3: 0x00830F10 | E3: ESXi 9.1
A4: AMD EPYC 7003/7003X Series | B4: 64C/128T | C4: 19.01 | D4: 0x00A00F11,0x00A00F12 | E4: ESXi 9.1
A5: AMD EPYC 8004 Series | B5: 64c/128t | C5: 19.A0 | D5: 0x00A10F11,0x00AA0F02 | E5: ESXi 9.1
A6: AMD EPYC 9004 Series | B6: 128c/256t | C6: 19.11 19.A0 | D6: 0x00A10F11,0x00A10F12,0x00AA0F02 | E6: ESXi 9.1
A7: AMD EPYC 9005 Series | B7: 192c/384t | C7: 1A.2 1A.11 | D7: 0x00B00F21,0x00B10F10 | E7: ESXi 9.1
A8: AMD Ryzen Embedded V1000 Series | B8: 4c/8t | C8: 17.11 | D8: 0x00810F10 | E8: ESXi 9.1
A9: Intel Atom C3000 Series | B9: 16c/16t | C9: 6.5F | D9: 0x000506F0 | E9: ESXi 9.1
A10: Intel Core i3/i5/i7-1100GRE Processor Series | C10: 6.8C 6.8D | D10: 0x000806C1,0x000806C2 | E10: ESXi 9.1
A11: Intel Xeon 6500P/6700P (Granite Rapids-SP) Series | B11: 86c/172t | C11: 6.AD.1 | D11: 0x000A06D1 | E11: ESXi 9.1
A12: Intel Xeon 6900P (Granite Rapids-AP) Series | C12: 6 AD 1 | D12: 0x000A06D1 | E12: ESXi 9.1
A13: Intel Xeon CPU Max 9400 (Sapphire-Rapids-HBM) Series | B13: 56c/112t | C13: 6.8F.8 | D13: 0x000806F8 | E13: ESXi 9.1
A14: Intel Xeon D-1700 (Ice-Lake-D) Series | B14: 20c/40t | C14: 6.6C.1 | D14: 0x000606C1 | E14: ESXi 9.1
A15: Intel Xeon D-2700 (Ice-Lake-D) Series | B15: 20c/40t | C15: 6.6C.1 | D15: 0x000606C1 | E15: ESXi 9.1
A16: Intel Xeon E-2100 Series | B16: 6c/112t | C16: 6.9E.A | D16: 0x000906EA,0x000906EB,0x000906EC | E16: ESXi 9.1
A17: Intel Xeon E-2200 (4 or 6-core) Series | B17: 6c/12t | C17: 6.9E.A | D17: 0x000906EA | E17: ESXi 9.1
A18: Intel Xeon E-2200 (8-core) Series | B18: 8c/16t | C18: 6.9E.D | D18: 0x000906ED | E18: ESXi 9.1
A19: Intel Xeon E-2300 Series | B19: 8c/16t | C19: 6.A7.1 | D19: 0x000A0671 | E19: ESXi 9.1
A20: Intel Xeon E-2400/Xeon 6300 Series | B20: 12c/24t | C20: 6.B7.1 | D20: 0x000B0671 | E20: ESXi 9.1
A21: Intel Xeon Gold 6200/5200 (Cascade-Lake-SP/Refresh) Series | B21: 28c/56t | C21: 6.55.7 | D21: 0x00050657 | E21: ESXi 9.1
A22: Intel Xeon Gold 6300/5300 (Cooper-Lake-SP) Series | B22: 28c/56t | C22: 6.55.B | D22: 0x0005065B | E22: ESXi 9.1
A23: Intel Xeon Gold 6300/5300 (Ice-Lake-SP) Series | B23: 32c/64t | C23: 6.6A.6 | D23: 0x000606A6 | E23: ESXi 9.1
A24: Intel Xeon Gold 6400/5400 (Sapphire-Rapids-SP) Series | B24: 60c/120t | C24: 6.8F.8 | D24: 0x000806F8 | E24: ESXi 9.1
... A36: Intel Xeon W-11000 Processor Series | B36: 8c/16t | C36: 6.8C 6.8D | D36: 0x000806C1,0x000806C2,0x000806D1 | E36: ESXi 9.1

Sheet GuestOS
A1: OS Vendors | B1: OS Release | C1: OS Arch | D1: Supported Releases | E1: Support Level
A2: AlmaLinux OS Foundation | B2: AlmaLinux OS 8.x | C2: x86(64-bit) | D2: ESXi 9.1 | E2: Supported
A3: AlmaLinux OS Foundation | B3: AlmaLinux OS 10.x | C3: x86(64-bit) | D3: ESXi 9.1 | E3: Supported
A4: AlmaLinux OS Foundation | B4: AlmaLinux OS 9.x | C4: x86(64-bit) | D4: ESXi 9.1 | E4: Supported
A5: Asianux | B5: Asianux 4.0 | C5: x86(32-bit) | D5: ESXi 9.1 | E5: Deprecated
A6: Asianux | B6: Asianux 7.0 | C6: x86(64-bit) | D6: ESXi 9.1 | E6: Legacy
A7: Asianux | B7: Asianux 4.0 | C7: x86(64-bit) | D7: ESXi 9.1 | E7: Deprecated
A8: Canonical Ltd | B8: Ubuntu 14.04 LTS | C8: x86(64-bit) | D8: ESXi 9.1 | E8: Legacy
A9: Canonical Ltd | B9: Ubuntu 25.04 | C9: x86(64-bit) | D9: ESXi 9.1 | E9: Legacy
A10: Canonical Ltd | B10: Ubuntu 25.10 | C10: x86(64-bit) | D10: ESXi 9.1 | E10: Supported
A11: Canonical Ltd | B11: Ubuntu 16.04 LTS | C11: x86(64-bit) | D11: ESXi 9.1 | E11: Supported
A12: Canonical Ltd | B12: Ubuntu 14.04 LTS | C12: x86(32-bit) | D12: ESXi 9.1 | E12: Legacy
... A130: xFusion Digital Technologies Co. Ltd | B130: FusionOS 22 | C130: x86(64-bit) | D130: ESXi 9.1 | E130: Supported

Sheet IODevices
A1: Brand Name | B1: Model | C1: Device Type | D1: Supported Releases | E1: _
A2: Adaptec | B2: Adaptec SmartRAID 3100 | C2: SAS-RAID | D2: ESXi 9.1 ESXi 9.0
A3: Adaptec | B3: Adaptec SmartRAID 3162-8i | C3: SAS-RAID | D3: ESXi 9.1 ESXi 9.0
A4: Adaptec | B4: Adaptec SmartHBA 2100-8i | C4: SAS-RAID | D4: ESXi 9.1 ESXi 9.0
A5: Adaptec | B5: Adaptec SmartHBA 2100-4i | C5: SAS-RAID | D5: ESXi 9.1 ESXi 9.0
A6: Adaptec | B6: Adaptec HBA 1100-8i | C6: SAS | D6: ESXi 9.1 ESXi 9.0
A7: Adaptec | B7: Adaptec HBA 1100-4i | C7: SAS | D7: ESXi 9.1 ESXi 9.0
A8: Adaptec | B8: Adaptec SmartHBA 2100-8e | C8: SAS-RAID | D8: ESXi 9.1 ESXi 9.0
A9: Adaptec | B9: Adaptec HBA 1100-8e | C9: SAS | D9: ESXi 9.1 ESXi 9.0
A10: Adaptec | B10: Adaptec SmartHBA 2100-4i4e | C10: SAS-RAID | D10: ESXi 9.1 ESXi 9.0
A11: Adaptec | B11: Adaptec HBA 1100 | C11: SAS | D11: ESXi 9.1 ESXi 9.0
A12: Adaptec | B12: Adaptec SmartHBA 2100 | C12: SAS-RAID | D12: ESXi 9.1 ESXi 9.0
A13: Adaptec | B13: Adaptec SmartHBA 2100A-8i | C13: SAS-RAID | D13: ESXi 9.1 ESXi 9.0
... A259: Broadcom | B259: MegaRAID SAS 9480-8i8e /w JBOD Mode | C259: SAS-SATA-NVME Tri-mode | D259: ESXi 9.1 ESXi 9.0
A260: Broadcom | B260: BCM57417 NetXtreme-E RDMA Partition | C260: Network | D260: ESXi 9.1 ESXi 9.0 | E260: Restricted
A261: Broadcom | B261: NetXtreme-E RDMA Virtual Function | C261: Network | D261: ESXi 9.1 ESXi 9.0 | E261: Restricted
A262: Broadcom | B262: BCM57417 NetXtreme-E Ethernet Partition | C262: Network | D262: ESXi 9.1 ESXi 9.0 | E262: Restricted
A263: Broadcom | B263: BCM57311 NetXtreme-C 10Gb RDMA Ethernet Controller | C263: Network | D263: ESXi 9.1 ESXi 9.0 | E263: Restricted
A264: Broadcom | B264: BCM57312 NetXtreme-C 10Gb/25Gb RDMA Ethernet Controller | C264: Network | D264: ESXi 9.1 ESXi 9.0 | E264: Restricted
A265: Broadcom | B265: BCM57414 NetXtreme-E 10Gb/25Gb RDMA Ethernet Controller | C265: Network | D265: ESXi 9.1 ESXi 9.0 | E265: Restricted
A266: Broadcom | B266: BCM57416 NetXtreme-E 10GBASE-T RDMA Ethernet Controller | C266: Network | D266: ESXi 9.1 ESXi 9.0 | E266: Restricted
A267: Broadcom | B267: BCM57417 NetXtreme-E 10GBASE-T RDMA Ethernet Controller | C267: Network | D267: ESXi 9.1 ESXi 9.0 | E267: Restricted
A268: Broadcom | B268: BCM57414 NetXtreme-E Ethernet Virtual Function | C268: Network | D268: ESXi 9.1 ESXi 9.0 | E268: Restricted
A269: Broadcom | B269: BCM57412 Broadcom NetXtreme-E Partition | C269: Network | D269: ESXi 9.1 ESXi 9.0 | E269: Restricted
A270: Broadcom | B270: BCM57314 NetXtreme-C 10Gb/25Gb/40Gb/50Gb RDMA Ethernet Controller | C270: Network | D270: ESXi 9.1 ESXi 9.0 | E270: Restricted
A271: Broadcom | B271: BCM57317 NetXtreme-C 10GBase-T RDMA Ethernet Controller | C271: Network | D271: ESXi 9.1 ESXi 9.0 | E271: Restricted
... A283: Broadcom | B283: BCM57412 NetXtreme-E 10Gb RDMA Ethernet Controller | C283: Network | D283: ESXi 9.1 ESXi 9.0 | E283: Restricted
A284: Broadcom | B284: BCM57412 | C284: Network | D284: ESXi 9.1 ESXi 9.0
A285: Broadcom | B285: BCM57412 | C285: Network | D285: ESXi 9.1 ESXi 9.0
A286: Broadcom | B286: BCM57412 | C286: Network | D286: ESXi 9.1 ESXi 9.0
A287: Broadcom | B287: BCM57412 | C287: Network | D287: ESXi 9.1 ESXi 9.0
A288: Broadcom | B288: BCM57412 | C288: Network | D288: ESXi 9.1 ESXi 9.0
A289: Broadcom | B289: BCM57412 | C289: Network | D289: ESXi 9.1 ESXi 9.0
A290: Broadcom | B290: MegaRAID SAS 9450-8i | C290: SAS-SATA-NVME Tri-mode RAID | D290: ESXi 9.1 ESXi 9.0
A291: Broadcom | B291: BCM57416 | C291: Network | D291: ESXi 9.1 ESXi 9.0
A292: Broadcom | B292: BCM57416 | C292: Network | D292: ESXi 9.1 ESXi 9.0
A293: Broadcom | B293: BCM57416 | C293: Network | D293: ESXi 9.1 ESXi 9.0
A294: Broadcom | B294: BCM57416 | C294: Network | D294: ESXi 9.1 ESXi 9.0
A295: Broadcom | B295: BCM57416 | C295: Network | D295: ESXi 9.1 ESXi 9.0
A296: Broadcom | B296: MegaRAID SAS 9461-16i | C296: SAS-SATA-NVME Tri-mode | D296: ESXi 9.1 ESXi 9.0
...

Sheet VCF Sizing
A1: Component | B1: Availability | C1: Size | D1: Nodes | E1: vCPU | F1: RAM (GB) | G1: Disk (GB) | H1: Location | I1: Required | J1: Design_IDs | K1: Funnel_CFG_IDs | L1: Doc_Ref | M1: Considerations | N1: Source_URL | O1: Notes
A2: Management Domain AVI Load Balancer | B2: HA | C2: Small | D2: 3 | E2: 18 | F2: 96 | G2: 1536 | H2: AVI Management Domain | I2: No | J2: DES-AVI-VALIDATE; DES-PNP; DES-OPTIONAL-DAYN | K2: VCF-AVI-REQD-CFG-001;VCF-AUTO-REQD-CFG-006 | L2: DES-AVI-VALIDATE | M2: DES-AVI-VALIDATE: Avi controller sizing: use P&P / Avi docs; cluster is typically 3 controllers when enabled. | DES-PNP: Confirm absolute vCPU/RAM/Disk from Planning & Preparation workbook Management Domain Sizing tab. | DES-OPTIONAL-DAYN: Optional/day-N component ‚Äî enable only when design needs it; may add MS worker capacity. | N2: https://techdocs.broadcom.com/us/en/vmware-cis/vcf/vcf-9-0-and-later/9-1/design/vmware-cloud-foundation-concepts/vcf-fleet-sizing-models-9-x.html
A3: Management Domain AVI Load Balancer | B3: HA | C3: Large | D3: 3 | E3: 48 | F3: 144 | G3: 4200 | H3: AVI Management Domain | I3: No | J3: DES-AVI-VALIDATE; DES-PNP; DES-OPTIONAL-DAYN | K3: VCF-AVI-REQD-CFG-001;VCF-AUTO-REQD-CFG-006 | L3: DES-AVI-VALIDATE | M3: DES-AVI-VALIDATE: Avi controller sizing: use P&P / Avi docs; cluster is typically 3 controllers when enabled. | DES-PNP: Confirm absolute vCPU/RAM/Disk from Planning & Preparation workbook Management Domain Sizing tab. | DES-OPTIONAL-DAYN: Optional/day-N component ‚Äî enable only when design needs it; may add MS worker capacity. | N3: https://techdocs.broadcom.com/us/en/vmware-cis/vcf/vcf-9-0-and-later/9-1/design/vmware-cloud-foundation-concepts/vcf-fleet-sizing-models-9-x.html
A4: Management Domain AVI Load Balancer | B4: HA | C4: X-Large | D4: 3 | E4: 48 | F4: 192 | G4: 5250 | H4: AVI Management Domain | I4: No | J4: DES-AVI-VALIDATE; DES-PNP; DES-OPTIONAL-DAYN | K4: VCF-AVI-REQD-CFG-001;VCF-AUTO-REQD-CFG-006 | L4: DES-AVI-VALIDATE | M4: DES-AVI-VALIDATE: Avi controller sizing: use P&P / Avi docs; cluster is typically 3 controllers when enabled. | DES-PNP: Confirm absolute vCPU/RAM/Disk from Planning & Preparation workbook Management Domain Sizing tab. | DES-OPTIONAL-DAYN: Optional/day-N component ‚Äî enable only when design needs it; may add MS worker capacity. | N4: https://techdocs.broadcom.com/us/en/vmware-cis/vcf/vcf-9-0-and-later/9-1/design/vmware-cloud-foundation-concepts/vcf-fleet-sizing-models-9-x.html
A5: Workload Domain AVI Load Balancer | B5: HA | C5: Small | D5: 3 | E5: 18 | F5: 96 | G5: 1536 | H5: AVI Workload Domain | I5: No | J5: DES-AVI-VALIDATE; DES-PNP; DES-OPTIONAL-DAYN | K5: VCF-AVI-REQD-CFG-001 | L5: DES-AVI-VALIDATE | M5: DES-AVI-VALIDATE: Avi controller sizing: use P&P / Avi docs; cluster is typically 3 controllers when enabled. | DES-PNP: Confirm absolute vCPU/RAM/Disk from Planning & Preparation workbook Management Domain Sizing tab. | DES-OPTIONAL-DAYN: Optional/day-N component ‚Äî enable only when design needs it; may add MS worker capacity. | N5: https://techdocs.broadcom.com/us/en/vmware-cis/vcf/vcf-9-0-and-later/9-1/design/vmware-cloud-foundation-concepts/vcf-fleet-sizing-models-9-x.html
A6: Workload Domain AVI Load Balancer | B6: HA | C6: Large | D6: 3 | E6: 48 | F6: 144 | G6: 4200 | H6: AVI Workload Domain | I6: No | J6: DES-AVI-VALIDATE; DES-PNP; DES-OPTIONAL-DAYN | K6: VCF-AVI-REQD-CFG-001 | L6: DES-AVI-VALIDATE | M6: DES-AVI-VALIDATE: Avi controller sizing: use P&P / Avi docs; cluster is typically 3 controllers when enabled. | DES-PNP: Confirm absolute vCPU/RAM/Disk from Planning & Preparation workbook Management Domain Sizing tab. | DES-OPTIONAL-DAYN: Optional/day-N component ‚Äî enable only when design needs it; may add MS worker capacity. | N6: https://techdocs.broadcom.com/us/en/vmware-cis/vcf/vcf-9-0-and-later/9-1/design/vmware-cloud-foundation-concepts/vcf-fleet-sizing-models-9-x.html
A7: Workload Domain AVI Load Balancer | B7: HA | C7: X-Large | D7: 3 | E7: 48 | F7: 192 | G7: 5250 | H7: AVI Workload Domain | I7: No | J7: DES-AVI-VALIDATE; DES-PNP; DES-OPTIONAL-DAYN | K7: VCF-AVI-REQD-CFG-001 | L7: DES-AVI-VALIDATE | M7: DES-AVI-VALIDATE: Avi controller sizing: use P&P / Avi docs; cluster is typically 3 controllers when enabled. | DES-PNP: Confirm absolute vCPU/RAM/Disk from Planning & Preparation workbook Management Domain Sizing tab. | DES-OPTIONAL-DAYN: Optional/day-N component ‚Äî enable only when design needs it; may add MS worker capacity. | N7: https://techdocs.broadcom.com/us/en/vmware-cis/vcf/vcf-9-0-and-later/9-1/design/vmware-cloud-foundation-concepts/vcf-fleet-sizing-models-9-x.html
A8: vDefend and AVI Licensing Hub | B8: HA | C8: Base | D8: 3 | E8: 10 | F8: 30 | G8: 710 | H8: Base with SSP in Management Domain | I8: No | J8: DES-AVI-VALIDATE; DES-PNP; DES-OPTIONAL-DAYN | L8: DES-AVI-VALIDATE | M8: DES-AVI-VALIDATE: Avi controller sizing: use P&P / Avi docs; cluster is typically 3 controllers when enabled. | DES-PNP: Confirm absolute vCPU/RAM/Disk from Planning & Preparation workbook Management Domain Sizing tab. | DES-OPTIONAL-DAYN: Optional/day-N component ‚Äî enable only when design needs it; may add MS worker capacity. | N8: https://techdocs.broadcom.com/us/en/vmware-cis/vcf/vcf-9-0-and-later/9-1/design/vmware-cloud-foundation-concepts/vcf-fleet-sizing-models-9-x.html
A9: Management Domain Security Services Platform | B9: HA | C9: Medium | D9: 9 | E9: 122 | F9: 444 | G9: 4806 | H9: Security Serices Platform Management Domain | I9: No | J9: DES-SSP-VALIDATE; DES-OPTIONAL-DAYN; DES-PNP | L9: DES-SSP-VALIDATE | M9: DES-SSP-VALIDATE: SSP node counts/sizes change by release ‚Äî validate against current Broadcom SSP sizing before SoW. | DES-OPTIONAL-DAYN: Optional/day-N component ‚Äî enable only when design needs it; may add MS worker capacity. | DES-PNP: Confirm absolute vCPU/RAM/Disk from Planning & Preparation workbook Management Domain Sizing tab. | N9: https://techdocs.broadcom.com/us/en/vmware-cis/vcf/vcf-9-0-and-later/9-1/design/vmware-cloud-foundation-concepts/vcf-fleet-sizing-models-9-x.html
A10: Management Domain Security Services Platform | B10: HA | C10: Large | D10: 12 | E10: 170 | F10: 636 | G10: 5830 | H10: Security Serices Platform Management Domain | I10: No | J10: DES-SSP-VALIDATE; DES-OPTIONAL-DAYN; DES-PNP | L10: DES-SSP-VALIDATE | M10: DES-SSP-VALIDATE: SSP node counts/sizes change by release ‚Äî validate against current Broadcom SSP sizing before SoW. | DES-OPTIONAL-DAYN: Optional/day-N component ‚Äî enable only when design needs it; may add MS worker capacity. | DES-PNP: Confirm absolute vCPU/RAM/Disk from Planning & Preparation workbook Management Domain Sizing tab. | N10: https://techdocs.broadcom.com/us/en/vmware-cis/vcf/vcf-9-0-and-later/9-1/design/vmware-cloud-foundation-concepts/vcf-fleet-sizing-models-9-x.html
A11: Management Domain Security Services Platform | B11: HA | C11: X-Large | D11: 14 | E11: 202 | F11: 764 | G11: 7366 | H11: Security Serices Platform Management Domain | I11: No | J11: DES-SSP-VALIDATE; DES-OPTIONAL-DAYN; DES-PNP | L11: DES-SSP-VALIDATE | M11: DES-SSP-VALIDATE: SSP node counts/sizes change by release ‚Äî validate against current Broadcom SSP sizing before SoW. | DES-OPTIONAL-DAYN: Optional/day-N component ‚Äî enable only when design needs it; may add MS worker capacity. | DES-PNP: Confirm absolute vCPU/RAM/Disk from Planning & Preparation workbook Management Domain Sizing tab. | N11: https://techdocs.broadcom.com/us/en/vmware-cis/vcf/vcf-9-0-and-later/9-1/design/vmware-cloud-foundation-concepts/vcf-fleet-sizing-models-9-x.html
A12: Workload Domain Security Services Platform | B12: HA | C12: Medium | D12: 9 | E12: 122 | F12: 444 | G12: 4806 | H12: Security Serices Platform Workload Domain | I12: No | J12: DES-SSP-VALIDATE; DES-OPTIONAL-DAYN; DES-PNP | L12: DES-SSP-VALIDATE | M12: DES-SSP-VALIDATE: SSP node counts/sizes change by release ‚Äî validate against current Broadcom SSP sizing before SoW. | DES-OPTIONAL-DAYN: Optional/day-N component ‚Äî enable only when design needs it; may add MS worker capacity. | DES-PNP: Confirm absolute vCPU/RAM/Disk from Planning & Preparation workbook Management Domain Sizing tab. | N12: https://techdocs.broadcom.com/us/en/vmware-cis/vcf/vcf-9-0-and-later/9-1/design/vmware-cloud-foundation-concepts/vcf-fleet-sizing-models-9-x.html
A13: Workload Domain Security Services Platform | B13: HA | C13: Large | D13: 12 | E13: 170 | F13: 636 | G13: 5830 | H13: Security Serices Platform Workload Domain | I13: No | J13: DES-SSP-VALIDATE; DES-OPTIONAL-DAYN; DES-PNP | L13: DES-SSP-VALIDATE | M13: DES-SSP-VALIDATE: SSP node counts/sizes change by release ‚Äî validate against current Broadcom SSP sizing before SoW. | DES-OPTIONAL-DAYN: Optional/day-N component ‚Äî enable only when design needs it; may add MS worker capacity. | DES-PNP: Confirm absolute vCPU/RAM/Disk from Planning & Preparation workbook Management Domain Sizing tab. | N13: https://techdocs.broadcom.com/us/en/vmware-cis/vcf/vcf-9-0-and-later/9-1/design/vmware-cloud-foundation-concepts/vcf-fleet-sizing-models-9-x.html
A14: Workload Domain Security Services Platform | B14: HA | C14: X-Large | D14: 14 | E14: 202 | F14: 764 | G14: 7366 | H14: Security Serices Platform Workload Domain | I14: No | J14: DES-SSP-VALIDATE; DES-OPTIONAL-DAYN; DES-PNP | L14: DES-SSP-VALIDATE | M14: DES-SSP-VALIDATE: SSP node counts/sizes change by release ‚Äî validate against current Broadcom SSP sizing before SoW. | DES-OPTIONAL-DAYN: Optional/day-N component ‚Äî enable only when design needs it; may add MS worker capacity. | DES-PNP: Confirm absolute vCPU/RAM/Disk from Planning & Preparation workbook Management Domain Sizing tab. | N14: https://techdocs.broadcom.com/us/en/vmware-cis/vcf/vcf-9-0-and-later/9-1/design/vmware-cloud-foundation-concepts/vcf-fleet-sizing-models-9-x.html
A15: Cloud Proxy | B15: HA | C15: Base | D15: 1 | E15: 4 | F15: 16 | G15: 264 | H15: VCF Fleet Components | I15: Yes | J15: VCF-OPS-REQD-COM-003; DES-PNP; DES-PROXY-HA | K15: VCF-EDGE-REQD-PAT-009 | L15: VCF-OPS-REQD-COM-003 | M15: VCF-OPS-REQD-COM-003: Deploy cloud proxy in default mgmt cluster to offload local metric/log collection. | DES-PNP: Confirm absolute vCPU/RAM/Disk from Planning & Preparation workbook Management Domain Sizing tab. | DES-PROXY-HA: Cloud Proxy: 1√ó Standard in HA Fleet models (still single appliance unless scaled). | N15: https://techdocs.broadcom.com/us/en/vmware-cis/vcf/vcf-9-0-and-later/9-1/design/vmware-cloud-foundation-concepts/vcf-operations.html
A16: Cloud Proxy | B16: Simple | C16: Small | D16: 1 | E16: 4 | F16: 16 | G16: 264 | H16: VCF Fleet Components | I16: No | J16: VCF-OPS-REQD-COM-003; DES-PNP; DES-PROXY-SIMPLE | K16: VCF-EDGE-REQD-PAT-009 | L16: VCF-OPS-REQD-COM-003 | M16: VCF-OPS-REQD-COM-003: Deploy cloud proxy in default mgmt cluster to offload local metric/log collection. | DES-PNP: Confirm absolute vCPU/RAM/Disk from Planning & Preparation workbook Management Domain Sizing tab. | DES-PROXY-SIMPLE: Cloud Proxy: 1√ó Small in Simple Fleet model. | N16: https://techdocs.broadcom.com/us/en/vmware-cis/vcf/vcf-9-0-and-later/9-1/design/vmware-cloud-foundation-concepts/vcf-operations.html | O16: migrated from 'Cloud Proxy - Simple'; Size was Simple ‚Üí Small; Availability=Simple; Required cleared (was Yes on Simple)
A17: VCF Automation | B17: HA | C17: Medium | D17: 3 | E17: 72 | F17: 288 | G17: 1002 | H17: VCF Fleet Components | I17: No | J17: VCF-AUTO-REQD-HA-001; DES-PNP | K17: VCF-AUTO-REQD-CFG-001;VCF-AUTO-REQD-CFG-002;VCF-AUTO-REQD-CFG-003;VCF-AUTO-REQD-CFG-006;VCF-AUTO-REQD-CFG-009;VCF-AUTO-REQD-CFG-010 | L17: VCF-AUTO-REQD-HA-001 | M17: VCF-AUTO-REQD-HA-001: HA Automation: three-node cluster (Medium/Large node sizes); optional external LB. | DES-PNP: Confirm absolute vCPU/RAM/Disk from Planning & Preparation workbook Management Domain Sizing tab. | N17: https://techdocs.broadcom.com/us/en/vmware-cis/vcf/vcf-9-0-and-later/9-1/design/design-library/vcf-automation-deployment-models-9-x/vcf-automation-high-availability-deployment-model.html
A18: VCF Automation | B18: HA | C18: Large | D18: 3 | E18: 96 | F18: 384 | G18: 1290 | H18: VCF Fleet Components | I18: No | J18: VCF-AUTO-REQD-HA-001; DES-PNP | K18: VCF-AUTO-REQD-CFG-001;VCF-AUTO-REQD-CFG-002;VCF-AUTO-REQD-CFG-003;VCF-AUTO-REQD-CFG-006;VCF-AUTO-REQD-CFG-009;VCF-AUTO-REQD-CFG-010 | L18: VCF-AUTO-REQD-HA-001 | M18: VCF-AUTO-REQD-HA-001: HA Automation: three-node cluster (Medium/Large node sizes); optional external LB. | DES-PNP: Confirm absolute vCPU/RAM/Disk from Planning & Preparation workbook Management Domain Sizing tab. | N18: https://techdocs.broadcom.com/us/en/vmware-cis/vcf/vcf-9-0-and-later/9-1/design/design-library/vcf-automation-deployment-models-9-x/vcf-automation-high-availability-deployment-model.html
A19: VCF Automation | B19: Simple | C19: Small | D19: 1 | E19: 24 | F19: 96 | G19: 717 | H19: VCF Fleet Components | I19: No | J19: VCF-AUTO-REQD-SIM-001; VCF-AUTO-REQD-SIM-002; DES-PNP | K19: VCF-AUTO-REQD-CFG-001;VCF-AUTO-REQD-CFG-003;VCF-AUTO-REQD-CFG-004;VCF-AUTO-REQD-CFG-010 | L19: VCF-AUTO-REQD-SIM-001 | M19: VCF-AUTO-REQD-SIM-001: Simple Automation: single node (defaults to small appliance); know scale/perf limits before production. | VCF-AUTO-REQD-SIM-002: Protect Automation Simple node with vSphere HA. | DES-PNP: Confirm absolute vCPU/RAM/Disk from Planning & Preparation workbook Management Domain Sizing tab. | N19: https://techdocs.broadcom.com/us/en/vmware-cis/vcf/vcf-9-0-and-later/9-1/design/design-library/vcf-automation-deployment-models-9-x/vcf-automation-simple-deployment-model.html | O19: migrated from 'VCF Automation - Simple'; Size was Simple ‚Üí Small; Availability=Simple
A20: VCF Operations | B20: HA | C20: Medium | D20: 3 | E20: 48 | F20: 144 | G20: 822 | H20: VCF Fleet Components | I20: Yes | J20: VCF-OPS-REQD-COM-001; DES-PNP; DES-FLEET-HA | K20: VCF-OPS-REQD-CFG-001;VCF-OPS-REQD-CFG-002;VCF-OPS-REQD-CFG-003;VCF-OPS-REQD-CFG-004;VCF-OPS-REQD-CFG-005;VCF-OPS-REQD-CFG-006;VCF-OPS-REQD-CFG-007;VCF-OPS-REQD-CFG-008 | L20: VCF-OPS-REQD-COM-001 | M20: VCF-OPS-REQD-COM-001: Fleet management components run on VCF management services in default mgmt cluster. | DES-PNP: Confirm absolute vCPU/RAM/Disk from Planning & Preparation workbook Management Domain Sizing tab. | DES-FLEET-HA: Fleet HA footprint: typically 3-node clustered appliances (Ops/NSX/Automation) + sized MS workers. | N20: https://techdocs.broadcom.com/us/en/vmware-cis/vcf/vcf-9-0-and-later/9-1/design/vmware-cloud-foundation-concepts/vcf-operations.html
A21: VCF Operations | B21: HA | C21: Large | D21: 3 | E21: 72 | F21: 384 | G21: 822 | H21: VCF Fleet Components | I21: No | J21: VCF-OPS-REQD-COM-001; DES-PNP; DES-FLEET-HA | K21: VCF-OPS-REQD-CFG-001;VCF-OPS-REQD-CFG-002;VCF-OPS-REQD-CFG-003;VCF-OPS-REQD-CFG-004;VCF-OPS-REQD-CFG-005;VCF-OPS-REQD-CFG-006;VCF-OPS-REQD-CFG-007;VCF-OPS-REQD-CFG-008 | L21: VCF-OPS-REQD-COM-001 | M21: VCF-OPS-REQD-COM-001: Fleet management components run on VCF management services in default mgmt cluster. | DES-PNP: Confirm absolute vCPU/RAM/Disk from Planning & Preparation workbook Management Domain Sizing tab. | DES-FLEET-HA: Fleet HA footprint: typically 3-node clustered appliances (Ops/NSX/Automation) + sized MS workers. | N21: https://techdocs.broadcom.com/us/en/vmware-cis/vcf/vcf-9-0-and-later/9-1/design/vmware-cloud-foundation-concepts/vcf-operations.html | O21: Required cleared (non-default HA size)
A22: VCF Operations | B22: Simple | C22: Small | D22: 1 | E22: 4 | F22: 16 | G22: 274 | H22: VCF Fleet Components | I22: No | J22: VCF-OPS-REQD-COM-001; DES-PNP; VCF-OPS-REQD-SIM-001; DES-FLEET-SIMPLE | K22: VCF-OPS-REQD-CFG-001;VCF-OPS-REQD-CFG-002;VCF-OPS-REQD-CFG-003;VCF-OPS-REQD-CFG-004 | L22: VCF-OPS-REQD-COM-001 | M22: VCF-OPS-REQD-COM-001: Fleet management components run on VCF management services in default mgmt cluster. | DES-PNP: Confirm absolute vCPU/RAM/Disk from Planning & Preparation workbook Management Domain Sizing tab. | VCF-OPS-REQD-SIM-001: Simple Ops: single analytics node in default mgmt cluster; no app-level HA; size to object scale. | DES-FLEET-SIMPLE: Fleet Simple footprint: prefer single-node appliances where model allows (lab/PoC/minimal). | N22: https://techdocs.broadcom.com/us/en/vmware-cis/vcf/vcf-9-0-and-later/9-1/design/design-blueprints-for/infrastructure-modernization/vcf-fleet-in-a-single-site-with-minimal-footprint-blueprint/management-domain-design-selections/operations-layer/simple-vcf-operations-model.html | O22: migrated from 'VCF Operations - Simple'; Size was Simple ‚Üí Small; Availability=Simple; Required cleared (was Yes on Simple)
A23: Management Domain NSX Edges | B23: HA | C23: Small | D23: 2 | E23: 4 | F23: 8 | G23: 400 | H23: VCF Management Domain | I23: No | J23: DES-PNP; DES-FLEET-HA; DES-OPTIONAL-DAYN | L23: DES-PNP | M23: DES-PNP: Confirm absolute vCPU/RAM/Disk from Planning & Preparation workbook Management Domain Sizing tab. | DES-FLEET-HA: Fleet HA footprint: typically 3-node clustered appliances (Ops/NSX/Automation) + sized MS workers. | DES-OPTIONAL-DAYN: Optional/day-N component ‚Äî enable only when design needs it; may add MS worker capacity. | N23: https://techdocs.broadcom.com/us/en/vmware-cis/vcf/vcf-9-0-and-later/9-1/design/vmware-cloud-foundation-concepts/vcf-fleet-sizing-models-9-x.html
A24: Management Domain NSX Edges | B24: HA | C24: Medium | D24: 2 | E24: 8 | F24: 16 | G24: 400 | H24: VCF Management Domain | I24: No | J24: DES-PNP; DES-FLEET-HA; DES-OPTIONAL-DAYN | L24: DES-PNP | M24: DES-PNP: Confirm absolute vCPU/RAM/Disk from Planning & Preparation workbook Management Domain Sizing tab. | DES-FLEET-HA: Fleet HA footprint: typically 3-node clustered appliances (Ops/NSX/Automation) + sized MS workers. | DES-OPTIONAL-DAYN: Optional/day-N component ‚Äî enable only when design needs it; may add MS worker capacity. | N24: https://techdocs.broadcom.com/us/en/vmware-cis/vcf/vcf-9-0-and-later/9-1/design/vmware-cloud-foundation-concepts/vcf-fleet-sizing-models-9-x.html
A25: Management Domain NSX Edges | B25: HA | C25: Large | D25: 2 | E25: 16 | F25: 64 | G25: 400 | H25: VCF Management Domain | I25: No | J25: DES-PNP; DES-FLEET-HA; DES-OPTIONAL-DAYN | L25: DES-PNP | M25: DES-PNP: Confirm absolute vCPU/RAM/Disk from Planning & Preparation workbook Management Domain Sizing tab. | DES-FLEET-HA: Fleet HA footprint: typically 3-node clustered appliances (Ops/NSX/Automation) + sized MS workers. | DES-OPTIONAL-DAYN: Optional/day-N component ‚Äî enable only when design needs it; may add MS worker capacity. | N25: https://techdocs.broadcom.com/us/en/vmware-cis/vcf/vcf-9-0-and-later/9-1/design/vmware-cloud-foundation-concepts/vcf-fleet-sizing-models-9-x.html
A26: Management Domain NSX Edges | B26: HA | C26: X-Large | D26: 2 | E26: 32 | F26: 128 | G26: 400 | H26: VCF Management Domain | I26: No | J26: DES-PNP; DES-FLEET-HA; DES-OPTIONAL-DAYN | L26: DES-PNP | M26: DES-PNP: Confirm absolute vCPU/RAM/Disk from Planning & Preparation workbook Management Domain Sizing tab. | DES-FLEET-HA: Fleet HA footprint: typically 3-node clustered appliances (Ops/NSX/Automation) + sized MS workers. | DES-OPTIONAL-DAYN: Optional/day-N component ‚Äî enable only when design needs it; may add MS worker capacity. | N26: https://techdocs.broadcom.com/us/en/vmware-cis/vcf/vcf-9-0-and-later/9-1/design/vmware-cloud-foundation-concepts/vcf-fleet-sizing-models-9-x.html
A27: Management Domain NSX Managers (Local / Global) | B27: HA | C27: Medium | D27: 3 | E27: 18 | F27: 72 | G27: 900 | H27: VCF Management Domain | I27: Yes | J27: DES-NSX-HA; DES-FLEET-HA; DES-PNP | K27: VCF-NSX-LM-REQD-CFG-001;VCF-NSX-LM-REQD-CFG-002;VCF-NSX-LM-REQD-CFG-004;VCF-NSX-LM-REQD-CFG-005 | L27: DES-NSX-HA | M27: DES-NSX-HA: HA NSX: 3 managers (Medium or Large per scale); needs host count for anti-affinity + VIP. | DES-FLEET-HA: Fleet HA footprint: typically 3-node clustered appliances (Ops/NSX/Automation) + sized MS workers. | DES-PNP: Confirm absolute vCPU/RAM/Disk from Planning & Preparation workbook Management Domain Sizing tab. | N27: https://techdocs.broadcom.com/us/en/vmware-cis/vcf/vcf-9-0-and-later/9-1/design/vmware-cloud-foundation-concepts/vcf-fleet-sizing-models-9-x.html
A28: Management Domain NSX Managers (Local / Global) | B28: HA | C28: Large | D28: 3 | E28: 36 | F28: 144 | G28: 900 | H28: VCF Management Domain | I28: No | J28: DES-NSX-HA; DES-FLEET-HA; DES-PNP | K28: VCF-NSX-LM-REQD-CFG-001;VCF-NSX-LM-REQD-CFG-002;VCF-NSX-LM-REQD-CFG-004;VCF-NSX-LM-REQD-CFG-005 | L28: DES-NSX-HA | M28: DES-NSX-HA: HA NSX: 3 managers (Medium or Large per scale); needs host count for anti-affinity + VIP. | DES-FLEET-HA: Fleet HA footprint: typically 3-node clustered appliances (Ops/NSX/Automation) + sized MS workers. | DES-PNP: Confirm absolute vCPU/RAM/Disk from Planning & Preparation workbook Management Domain Sizing tab. | N28: https://techdocs.broadcom.com/us/en/vmware-cis/vcf/vcf-9-0-and-later/9-1/design/vmware-cloud-foundation-concepts/vcf-fleet-sizing-models-9-x.html | O28: Required cleared (non-default HA size)
A29: Management Domain NSX Managers (Local / Global) | B29: Simple | C29: Small | D29: 1 | E29: 6 | F29: 24 | G29: 300 | H29: VCF Management Domain | I29: No | J29: DES-NSX-SIMPLE; DES-FLEET-SIMPLE; DES-PNP | K29: VCF-NSX-LM-REQD-CFG-001;VCF-NSX-LM-REQD-CFG-005 | L29: DES-NSX-SIMPLE | M29: DES-NSX-SIMPLE: Simple NSX: 1√ó Medium manager (not a 3-node cluster). | DES-FLEET-SIMPLE: Fleet Simple footprint: prefer single-node appliances where model allows (lab/PoC/minimal). | DES-PNP: Confirm absolute vCPU/RAM/Disk from Planning & Preparation workbook Management Domain Sizing tab. | N29: https://techdocs.broadcom.com/us/en/vmware-cis/vcf/vcf-9-0-and-later/9-1/design/vmware-cloud-foundation-concepts/vcf-fleet-sizing-models-9-x.html | O29: migrated from 'Management Domain NSX Managers (Simple)'; Size was Simple ‚Üí Small; Availability=Simple; aligned to HA NSX component name '(Local / Global)'; Required cleared (was Yes on Simple)
A30: Management Domain Virtual Network Appliances | B30: HA | C30: Small | D30: 2 | E30: 4 | F30: 8 | G30: 400 | H30: VCF Management Domain | I30: No | J30: DES-PNP; DES-FLEET-HA; DES-OPTIONAL-DAYN | L30: DES-PNP | M30: DES-PNP: Confirm absolute vCPU/RAM/Disk from Planning & Preparation workbook Management Domain Sizing tab. | DES-FLEET-HA: Fleet HA footprint: typically 3-node clustered appliances (Ops/NSX/Automation) + sized MS workers. | DES-OPTIONAL-DAYN: Optional/day-N component ‚Äî enable only when design needs it; may add MS worker capacity. | N30: https://techdocs.broadcom.com/us/en/vmware-cis/vcf/vcf-9-0-and-later/9-1/design/vmware-cloud-foundation-concepts/vcf-fleet-sizing-models-9-x.html
A31: Management Domain Virtual Network Appliances | B31: HA | C31: Medium | D31: 2 | E31: 8 | F31: 16 | G31: 400 | H31: VCF Management Domain | I31: No | J31: DES-PNP; DES-FLEET-HA; DES-OPTIONAL-DAYN | L31: DES-PNP | M31: DES-PNP: Confirm absolute vCPU/RAM/Disk from Planning & Preparation workbook Management Domain Sizing tab. | DES-FLEET-HA: Fleet HA footprint: typically 3-node clustered appliances (Ops/NSX/Automation) + sized MS workers. | DES-OPTIONAL-DAYN: Optional/day-N component ‚Äî enable only when design needs it; may add MS worker capacity. | N31: https://techdocs.broadcom.com/us/en/vmware-cis/vcf/vcf-9-0-and-later/9-1/design/vmware-cloud-foundation-concepts/vcf-fleet-sizing-models-9-x.html
A32: Management Domain Virtual Network Appliances | B32: HA | C32: Large | D32: 2 | E32: 16 | F32: 64 | G32: 400 | H32: VCF Management Domain | I32: No | J32: DES-PNP; DES-FLEET-HA; DES-OPTIONAL-DAYN | L32: DES-PNP | M32: DES-PNP: Confirm absolute vCPU/RAM/Disk from Planning & Preparation workbook Management Domain Sizing tab. | DES-FLEET-HA: Fleet HA footprint: typically 3-node clustered appliances (Ops/NSX/Automation) + sized MS workers. | DES-OPTIONAL-DAYN: Optional/day-N component ‚Äî enable only when design needs it; may add MS worker capacity. | N32: https://techdocs.broadcom.com/us/en/vmware-cis/vcf/vcf-9-0-and-later/9-1/design/vmware-cloud-foundation-concepts/vcf-fleet-sizing-models-9-x.html
A33: Management Domain Virtual Network Appliances | B33: HA | C33: X-Large | D33: 2 | E33: 32 | F33: 128 | G33: 400 | H33: VCF Management Domain | I33: No | J33: DES-PNP; DES-FLEET-HA; DES-OPTIONAL-DAYN | L33: DES-PNP | M33: DES-PNP: Confirm absolute vCPU/RAM/Disk from Planning & Preparation workbook Management Domain Sizing tab. | DES-FLEET-HA: Fleet HA footprint: typically 3-node clustered appliances (Ops/NSX/Automation) + sized MS workers. | DES-OPTIONAL-DAYN: Optional/day-N component ‚Äî enable only when design needs it; may add MS worker capacity. | N33: https://techdocs.broadcom.com/us/en/vmware-cis/vcf/vcf-9-0-and-later/9-1/design/vmware-cloud-foundation-concepts/vcf-fleet-sizing-models-9-x.html
A34: Management Domain vCenter | B34: HA | C34: Medium | D34: 1 | E34: 8 | F34: 30 | G34: 1658 | H34: VCF Management Domain | I34: Yes | J34: DES-VC-HA; DES-FLEET-HA; DES-PNP | K34: VCF-VC-REQD-CFG-001;VCF-VC-REQD-CFG-003;VCF-VC-REQD-CFG-005 | L34: DES-VC-HA | M34: DES-VC-HA: vCenter Medium/Large per Fleet sizing; single VC appliance (availability via vSphere HA, not a 3-node VC cluster). | DES-FLEET-HA: Fleet HA footprint: typically 3-node clustered appliances (Ops/NSX/Automation) + sized MS workers. | DES-PNP: Confirm absolute vCPU/RAM/Disk from Planning & Preparation workbook Management Domain Sizing tab. | N34: https://techdocs.broadcom.com/us/en/vmware-cis/vcf/vcf-9-0-and-later/9-1/design/vmware-cloud-foundation-concepts/vcf-fleet-sizing-models-9-x.html
A35: Management Domain vCenter | B35: HA | C35: Large | D35: 1 | E35: 16 | F35: 39 | G35: 3088 | H35: VCF Management Domain | I35: No | J35: DES-VC-HA; DES-FLEET-HA; DES-PNP | K35: VCF-VC-REQD-CFG-001;VCF-VC-REQD-CFG-003;VCF-VC-REQD-CFG-005 | L35: DES-VC-HA | M35: DES-VC-HA: vCenter Medium/Large per Fleet sizing; single VC appliance (availability via vSphere HA, not a 3-node VC cluster). | DES-FLEET-HA: Fleet HA footprint: typically 3-node clustered appliances (Ops/NSX/Automation) + sized MS workers. | DES-PNP: Confirm absolute vCPU/RAM/Disk from Planning & Preparation workbook Management Domain Sizing tab. | N35: https://techdocs.broadcom.com/us/en/vmware-cis/vcf/vcf-9-0-and-later/9-1/design/vmware-cloud-foundation-concepts/vcf-fleet-sizing-models-9-x.html | O35: Required cleared (non-default HA size)
A36: Management Domain vCenter | B36: Simple | C36: Small | D36: 1 | E36: 4 | F36: 8 | G36: 1519 | H36: VCF Management Domain | I36: No | J36: DES-VC-SIMPLE; DES-FLEET-SIMPLE; DES-PNP | K36: VCF-VC-REQD-CFG-001;VCF-VC-REQD-CFG-003;VCF-VC-REQD-CFG-005 | L36: DES-VC-SIMPLE | M36: DES-VC-SIMPLE: Simple vCenter: Small appliance class per Fleet Simple model. | DES-FLEET-SIMPLE: Fleet Simple footprint: prefer single-node appliances where model allows (lab/PoC/minimal). | DES-PNP: Confirm absolute vCPU/RAM/Disk from Planning & Preparation workbook Management Domain Sizing tab. | N36: https://techdocs.broadcom.com/us/en/vmware-cis/vcf/vcf-9-0-and-later/9-1/design/vmware-cloud-foundation-concepts/vcf-fleet-sizing-models-9-x.html | O36: migrated from 'Management Domain vCenter - Simple'; Size was Simple ‚Üí Small; Availability=Simple; Required cleared (was Yes on Simple)
A37: Identity Broker | B37: HA | C37: Base | D37: 3 | E37: 24 | F37: 48 | G37: 150 | H37: VCF Management Services | I37: Yes | J37: DES-MS-HOSTED; VCF-MS-REQD-COM-001; VCF-MS-REQD-HA-001 | K37: VCF-AUTO-REQD-CFG-004 | L37: VCF-MS-REQD-COM-001 | M37: DES-MS-HOSTED: Runs as a workload on the VCF services runtime; inherits Simple vs HA from the runtime model (SIM-001 / HA-001 on control+worker rows). | VCF-MS-REQD-COM-001: Allocate IP range for all planned control + worker nodes (day-N scale-out consumes more). | VCF-MS-REQD-HA-001: HA MS: deploy 3 control-plane nodes + workers for chosen size (Medium/Large); higher resource cost. | N37: https://techdocs.broadcom.com/us/en/vmware-cis/vcf/vcf-9-0-and-later/9-1/design/vmware-cloud-foundation-concepts/vcf-management-services-models.html
A38: Identity Broker | B38: Simple | C38: Small | D38: 1 | E38: 24 | F38: 48 | G38: 150 | H38: VCF Management Services | I38: No | J38: DES-MS-HOSTED; VCF-MS-REQD-COM-001; VCF-MS-REQD-SIM-001 | K38: VCF-AUTO-REQD-CFG-004 | L38: VCF-MS-REQD-COM-001 | M38: DES-MS-HOSTED: Runs as a workload on the VCF services runtime; inherits Simple vs HA from the runtime model (SIM-001 / HA-001 on control+worker rows). | VCF-MS-REQD-COM-001: Allocate IP range for all planned control + worker nodes (day-N scale-out consumes more). | VCF-MS-REQD-SIM-001: Simple MS: deploy 1 control-plane + 3 workers in default mgmt cluster; CP loss ‚áí redeploy/restore. | N38: https://techdocs.broadcom.com/us/en/vmware-cis/vcf/vcf-9-0-and-later/9-1/design/vmware-cloud-foundation-concepts/vcf-management-services-models.html | O38: migrated from 'Identity Broker - Simple'; Size was Simple ‚Üí Small; Availability=Simple; Required cleared (was Yes on Simple)
A39: License Server | B39: HA | C39: Base | D39: 1 | E39: 2 | F39: 4 | G39: 12 | H39: VCF Management Services | I39: Yes | J39: DES-LICENSE; DES-PNP | K39: VCF-LIC-REQD-CFG-001;VCF-LIC-RCMD-CFG-002 | L39: DES-LICENSE | M39: DES-LICENSE: License Server: 1√ó Default in both Simple and HA Fleet models. | DES-PNP: Confirm absolute vCPU/RAM/Disk from Planning & Preparation workbook Management Domain Sizing tab. | N39: https://techdocs.broadcom.com/us/en/vmware-cis/vcf/vcf-9-0-and-later/9-1/design/vmware-cloud-foundation-concepts/vcf-fleet-sizing-models-9-x.html
A40: License Server | B40: Simple | C40: Small | D40: 1 | E40: 2 | F40: 4 | G40: 12 | H40: VCF Management Services | I40: No | J40: DES-LICENSE; DES-PNP | K40: VCF-LIC-REQD-CFG-001;VCF-LIC-RCMD-CFG-002 | L40: DES-LICENSE | M40: DES-LICENSE: License Server: 1√ó Default in both Simple and HA Fleet models. | DES-PNP: Confirm absolute vCPU/RAM/Disk from Planning & Preparation workbook Management Domain Sizing tab. | N40: https://techdocs.broadcom.com/us/en/vmware-cis/vcf/vcf-9-0-and-later/9-1/design/vmware-cloud-foundation-concepts/vcf-fleet-sizing-models-9-x.html | O40: migrated from 'License Server - Simple'; Size was Simple ‚Üí Small; Availability=Simple; Required cleared (was Yes on Simple)
...

Sheet Design IDs
A1: ID | B1: Bucket | C1: Title | D1: Decision Type | E1: Trigger Criteria | F1: Requirement | G1: Justification | H1: Parent Decision IDs | I1: Baseline Bundle ID | J1: Rule Classification | K1: Mapping Status | L1: Mapping Rationale | M1: Source Version | N1: Source URL | O1: Source Match
A2: VCF-PAI-REQD-CFG-001 | B2: AI | C2: GPU Host Profiling | D2: Required | E2: hldIncAI=true | F2: Ensure all hosts in the AI workload domain have identical NVIDIA GPU hardware and profiles. | G2: Guarantees DRS load balancing and vMotion compatibility for AI/ML workloads. | H2: DEC-AI-001; DEC-AI-002; DEC-NET-004 | I2: BL-SOL-001 | J2: DECISION_LED | K2: MAPPED | L2: Activated by hldIncAI=true; governed by DEC-AI-001, DEC-AI-002, DEC-NET-004. | M2: VCF 9.1 | N2: https://techdocs.broadcom.com/us/en/vmware-cis/vcf/vcf-9-0-and-later/9-1/design/design-library/private-ai-platform-detailed-design.html | O2: prefix:VCF-PAI-
A3: VCF-PAI-REQD-CFG-002 | B3: AI | C3: Backend AI Network | D3: Required | E3: hldIncAI=true | F3: Allocate a dedicated high-throughput, low-latency VLAN (RoCEv2) for GPU-to-GPU communications. | G3: Prevents deep learning network traffic from bottlenecking standard VM traffic. | H3: DEC-AI-001; DEC-AI-002; DEC-NET-004 | I3: BL-SOL-001 | J3: DECISION_LED | K3: MAPPED | L3: Activated by hldIncAI=true; governed by DEC-AI-001, DEC-AI-002, DEC-NET-004. | M3: VCF 9.1 | N3: https://techdocs.broadcom.com/us/en/vmware-cis/vcf/vcf-9-0-and-later/9-1/design/design-library/private-ai-platform-detailed-design.html | O3: prefix:VCF-PAI-
A4: VCF-PAI-REQD-CFG-003 | B4: AI | C4: NVIDIA Licensing System | D4: Required | E4: ALWAYS | F4: Deploy the NVIDIA License System (NLS) appliance in the management domain. | G4: Centralizes vGPU license distribution for tenant workload clusters. | H4: DEC-AI-001; DEC-AI-002 | I4: BL-SOL-001 | J4: INHERIT_PARENT_SCOPE | K4: MAPPED | L4: Required after parent decision DEC-AI-001, DEC-AI-002 activates this domain or solution. | M4: VCF 9.1 | N4: https://techdocs.broadcom.com/us/en/vmware-cis/vcf/vcf-9-0-and-later/9-1/design/design-library/private-ai-platform-detailed-design.html | O4: prefix:VCF-PAI-
A5: VCF-PAI-REQD-CFG-004 | B5: AI | C5: AI Workload Orchestration Model | D5: Required | E5: ALWAYS | F5: Determine whether AI/ML workloads will be scheduled via an MLOps orchestration platform (e.g., Run:ai, NVIDIA AI Enterprise tooling) or managed directly through vCenter/vGPU assignment. | G5: Orchestration model determines whether GPU capacity is exposed as an aggregate pool or requires explicit per-VM MIG/vGPU partition design; getting this wrong means re-architecting GPU allocation later. | H5: DEC-AI-001; DEC-AI-002 | I5: BL-SOL-001 | J5: INHERIT_PARENT_SCOPE | K5: MAPPED | L5: Required after parent decision DEC-AI-001, DEC-AI-002 activates this domain or solution. | M5: VCF 9.1 | N5: https://techdocs.broadcom.com/us/en/vmware-cis/vcf/vcf-9-0-and-later/9-1/design/design-library/private-ai-platform-detailed-design.html | O5: prefix:VCF-PAI-
A6: VCF-AUTO-REQD-CFG-001 | B6: AUTO | C6: VCF Automation Placement | D6: Required | E6: ALWAYS | F6: Deploy VCF Automation in the management domain or a dedicated management cluster. | G6: Secures the automation and orchestration engine within the primary administrative boundary. | H6: DEC-AUTO-001; DEC-AUTO-002 | I6: BL-SOL-001 | J6: INHERIT_PARENT_SCOPE | K6: MAPPED | L6: Required after parent decision DEC-AUTO-001, DEC-AUTO-002 activates this domain or solution. | M6: VCF 9.1 | N6: https://techdocs.broadcom.com/us/en/vmware-cis/vcf/vcf-9-0-and-later/9-1/design/design-library/vcf-automation-deployment-models-9-x.html | O6: prefix:VCF-AUTO-
A7: VCF-AUTO-REQD-CFG-002 | B7: AUTO | C7: VCF Automation HA | D7: Required | E7: availabilityModel=HA | F7: Deploy a cluster of three VCF Automation appliances for high availability. | G7: Guarantees continuous self-service and orchestration during host or node failures. | H7: DEC-AUTO-001; DEC-AUTO-002 | I7: BL-SOL-001 | J7: INHERIT_PARENT_SCOPE | K7: MAPPED | L7: Required after parent decision DEC-AUTO-001, DEC-AUTO-002 activates this domain or solution. | M7: VCF 9.1 | N7: https://techdocs.broadcom.com/us/en/vmware-cis/vcf/vcf-9-0-and-later/9-1/design/design-library/vcf-automation-deployment-models-9-x.html | O7: prefix:VCF-AUTO-
A8: VCF-AUTO-REQD-CFG-004 | B8: AUTO | C8: Identity Broker Integration | D8: Required | E8: ALWAYS | F8: Integrate VCF Automation with Identity Broker. | G8: Standardizes Role-Based Access Control (RBAC) and single sign-on across the VCF portal. | H8: DEC-AUTO-001; DEC-ID-001; DEC-AUTO-002 | I8: BL-SOL-001 | J8: INHERIT_PARENT_SCOPE | K8: MAPPED | L8: Required after parent decision DEC-AUTO-001, DEC-ID-001, DEC-AUTO-002 activates this domain or solution. | M8: VCF 9.1 | N8: https://techdocs.broadcom.com/us/en/vmware-cis/vcf/vcf-9-0-and-later/9-1/design/design-library/vcf-automation-deployment-models-9-x.html | O8: prefix:VCF-AUTO-
A9: VCF-AUTO-REQD-CFG-005 | B9: AUTO | C9: NSX Cloud Accounts | D9: Required | E9: ALWAYS | F9: Configure NSX cloud accounts within VCF Automation to enable on-demand network provisioning. | G9: Allows developers to dynamically spin up load balancers and networks via self-service blueprints. | H9: DEC-AUTO-001; DEC-AUTO-002 | I9: BL-SOL-001 | J9: INHERIT_PARENT_SCOPE | K9: MAPPED | L9: Required after parent decision DEC-AUTO-001, DEC-AUTO-002 activates this domain or solution. | M9: VCF 9.1 | N9: https://techdocs.broadcom.com/us/en/vmware-cis/vcf/vcf-9-0-and-later/9-1/design/design-library/vcf-automation-deployment-models-9-x.html | O9: prefix:VCF-AUTO-
A10: VCF-AUTO-REQD-CFG-006 | B10: AUTO | C10: VCF Auto Load Balancer | D10: Required | E10: ALWAYS | F10: Deploy an Avi or equivalent to front the VCF Automation cluster. | G10: Ensures highly available access to the self-service portal for developers and users. | H10: DEC-AUTO-001; DEC-NET-004; DEC-AUTO-002 | I10: BL-SOL-001 | J10: INHERIT_PARENT_SCOPE | K10: MAPPED | L10: Required after parent decision DEC-AUTO-001, DEC-NET-004, DEC-AUTO-002 activates this domain or solution. | M10: VCF 9.1 | N10: https://techdocs.broadcom.com/us/en/vmware-cis/vcf/vcf-9-0-and-later/9-1/design/design-library/vcf-automation-deployment-models-9-x.html | O10: prefix:VCF-AUTO-
A11: VCF-AUTO-REQD-CFG-007 | B11: AUTO | C11: Automation Extensibility | D11: Required | E11: ALWAYS | F11: Deploy VCF Automation Orchestrator nodes independently if complex scripting exceeds built-in capabilities. | G11: Offloads heavy API interaction and customized workflows from the core Automation appliances. | H11: DEC-AUTO-001; DEC-AUTO-002 | I11: BL-SOL-001 | J11: INHERIT_PARENT_SCOPE | K11: MAPPED | L11: Required after parent decision DEC-AUTO-001, DEC-AUTO-002 activates this domain or solution. | M11: VCF 9.1 | N11: https://techdocs.broadcom.com/us/en/vmware-cis/vcf/vcf-9-0-and-later/9-1/design/design-library/vcf-automation-deployment-models-9-x.html | O11: prefix:VCF-AUTO-
A12: VCF-AUTO-REQD-CFG-008 | B12: AUTO | C12: Cloud Zone Grouping | D12: Required | E12: ALWAYS | F12: Group vCenter compute clusters into VCF Automation Cloud Zones by SLA or purpose. | G12: Allows fine-grained placement policies for developer blueprints targeting specific hardware tiers. | H12: DEC-AUTO-001; DEC-AUTO-002 | I12: BL-SOL-001 | J12: INHERIT_PARENT_SCOPE | K12: MAPPED | L12: Required after parent decision DEC-AUTO-001, DEC-AUTO-002 activates this domain or solution. | M12: VCF 9.1 | N12: https://techdocs.broadcom.com/us/en/vmware-cis/vcf/vcf-9-0-and-later/9-1/design/design-library/vcf-automation-deployment-models-9-x.html | O12: prefix:VCF-AUTO-
... A164: DES-MS-HOSTED | B164: FLEET | C164: MS-Hosted Component Inherits Topology | D164: Required | E164: ALWAYS | F164: Treat Identity Broker, Real-time Metrics, Log Management, and Software Depot as workloads hosted on VCF services runtime; inherit Simple vs HA from MS topology (SIM-001 / HA-001). | G164: Avoids duplicating CP/worker topology rules onto every hosted service row. | H164: DEC-FLEET-001; DEC-AVAIL-002 | I164: BL-MGMT-001 | J164: DECISION_LED | K164: NEW_SIZING_BRIDGE | L164: Imported from Broadcom TechDocs design requirement tables. | M164: VCF 9.1 | N164: https://techdocs.broadcom.com/us/en/vmware-cis/vcf/vcf-9-0-and-later/9-1/design/vmware-cloud-foundation-concepts/vcf-management-services-models.html | O164: preexisting-techdocs

Sheet Design Bridge
A1: Component | B1: Availability | C1: Size | D1: TechDocs_or_DES_IDs | E1: Funnel_CFG_IDs | F1: Bridge_Note | G1: Source_URL
A2: Management Domain AVI Load Balancer | B2: HA | C2: Small | D2: DES-AVI-VALIDATE;DES-PNP;DES-OPTIONAL-DAYN | E2: VCF-AVI-REQD-CFG-001;VCF-AUTO-REQD-CFG-006 | F2: Avi controllers in mgmt domain. | G2: https://techdocs.broadcom.com/us/en/vmware-cis/vcf/vcf-9-0-and-later/9-1/design/vmware-cloud-foundation-concepts/vcf-fleet-sizing-models-9-x.html
A3: Management Domain AVI Load Balancer | B3: HA | C3: Large | D3: DES-AVI-VALIDATE;DES-PNP;DES-OPTIONAL-DAYN | E3: VCF-AVI-REQD-CFG-001;VCF-AUTO-REQD-CFG-006 | F3: Avi controllers in mgmt domain. | G3: https://techdocs.broadcom.com/us/en/vmware-cis/vcf/vcf-9-0-and-later/9-1/design/vmware-cloud-foundation-concepts/vcf-fleet-sizing-models-9-x.html
A4: Management Domain AVI Load Balancer | B4: HA | C4: X-Large | D4: DES-AVI-VALIDATE;DES-PNP;DES-OPTIONAL-DAYN | E4: VCF-AVI-REQD-CFG-001;VCF-AUTO-REQD-CFG-006 | F4: Avi controllers in mgmt domain. | G4: https://techdocs.broadcom.com/us/en/vmware-cis/vcf/vcf-9-0-and-later/9-1/design/vmware-cloud-foundation-concepts/vcf-fleet-sizing-models-9-x.html
A5: Workload Domain AVI Load Balancer | B5: HA | C5: Small | D5: DES-AVI-VALIDATE;DES-PNP;DES-OPTIONAL-DAYN | E5: VCF-AVI-REQD-CFG-001 | F5: Optional WLD Avi footprint. | G5: https://techdocs.broadcom.com/us/en/vmware-cis/vcf/vcf-9-0-and-later/9-1/design/vmware-cloud-foundation-concepts/vcf-fleet-sizing-models-9-x.html
A6: Workload Domain AVI Load Balancer | B6: HA | C6: Large | D6: DES-AVI-VALIDATE;DES-PNP;DES-OPTIONAL-DAYN | E6: VCF-AVI-REQD-CFG-001 | F6: Optional WLD Avi footprint. | G6: https://techdocs.broadcom.com/us/en/vmware-cis/vcf/vcf-9-0-and-later/9-1/design/vmware-cloud-foundation-concepts/vcf-fleet-sizing-models-9-x.html
A7: Workload Domain AVI Load Balancer | B7: HA | C7: X-Large | D7: DES-AVI-VALIDATE;DES-PNP;DES-OPTIONAL-DAYN | E7: VCF-AVI-REQD-CFG-001 | F7: Optional WLD Avi footprint. | G7: https://techdocs.broadcom.com/us/en/vmware-cis/vcf/vcf-9-0-and-later/9-1/design/vmware-cloud-foundation-concepts/vcf-fleet-sizing-models-9-x.html
A8: vDefend and AVI Licensing Hub | B8: HA | C8: Base | D8: DES-AVI-VALIDATE;DES-PNP;DES-OPTIONAL-DAYN | F8: No Funnel bridge yet ‚Äî keep DES-PNP / Fleet fallback; extend bridge as needed. | G8: https://techdocs.broadcom.com/us/en/vmware-cis/vcf/vcf-9-0-and-later/9-1/design/vmware-cloud-foundation-concepts/vcf-fleet-sizing-models-9-x.html
A9: Management Domain Security Services Platform | B9: HA | C9: Medium | D9: DES-SSP-VALIDATE;DES-OPTIONAL-DAYN;DES-PNP | F9: No Funnel bridge yet ‚Äî keep DES-PNP / Fleet fallback; extend bridge as needed. | G9: https://techdocs.broadcom.com/us/en/vmware-cis/vcf/vcf-9-0-and-later/9-1/design/vmware-cloud-foundation-concepts/vcf-fleet-sizing-models-9-x.html
A10: Management Domain Security Services Platform | B10: HA | C10: Large | D10: DES-SSP-VALIDATE;DES-OPTIONAL-DAYN;DES-PNP | F10: No Funnel bridge yet ‚Äî keep DES-PNP / Fleet fallback; extend bridge as needed. | G10: https://techdocs.broadcom.com/us/en/vmware-cis/vcf/vcf-9-0-and-later/9-1/design/vmware-cloud-foundation-concepts/vcf-fleet-sizing-models-9-x.html
A11: Management Domain Security Services Platform | B11: HA | C11: X-Large | D11: DES-SSP-VALIDATE;DES-OPTIONAL-DAYN;DES-PNP | F11: No Funnel bridge yet ‚Äî keep DES-PNP / Fleet fallback; extend bridge as needed. | G11: https://techdocs.broadcom.com/us/en/vmware-cis/vcf/vcf-9-0-and-later/9-1/design/vmware-cloud-foundation-concepts/vcf-fleet-sizing-models-9-x.html
A12: Workload Domain Security Services Platform | B12: HA | C12: Medium | D12: DES-SSP-VALIDATE;DES-OPTIONAL-DAYN;DES-PNP | F12: No Funnel bridge yet ‚Äî keep DES-PNP / Fleet fallback; extend bridge as needed. | G12: https://techdocs.broadcom.com/us/en/vmware-cis/vcf/vcf-9-0-and-later/9-1/design/vmware-cloud-foundation-concepts/vcf-fleet-sizing-models-9-x.html
A13: Workload Domain Security Services Platform | B13: HA | C13: Large | D13: DES-SSP-VALIDATE;DES-OPTIONAL-DAYN;DES-PNP | F13: No Funnel bridge yet ‚Äî keep DES-PNP / Fleet fallback; extend bridge as needed. | G13: https://techdocs.broadcom.com/us/en/vmware-cis/vcf/vcf-9-0-and-later/9-1/design/vmware-cloud-foundation-concepts/vcf-fleet-sizing-models-9-x.html
A14: Workload Domain Security Services Platform | B14: HA | C14: X-Large | D14: DES-SSP-VALIDATE;DES-OPTIONAL-DAYN;DES-PNP | F14: No Funnel bridge yet ‚Äî keep DES-PNP / Fleet fallback; extend bridge as needed. | G14: https://techdocs.broadcom.com/us/en/vmware-cis/vcf/vcf-9-0-and-later/9-1/design/vmware-cloud-foundation-concepts/vcf-fleet-sizing-models-9-x.html
A15: Cloud Proxy | B15: HA | C15: Base | D15: VCF-OPS-REQD-COM-003;DES-PNP;DES-PROXY-HA | E15: VCF-EDGE-REQD-PAT-009 | F15: PAT-009 is edge/latency-triggered; keep COM-003 as TechDocs deploy rule. | G15: https://techdocs.broadcom.com/us/en/vmware-cis/vcf/vcf-9-0-and-later/9-1/design/vmware-cloud-foundation-concepts/vcf-operations.html
A16: Cloud Proxy | B16: Simple | C16: Small | D16: VCF-OPS-REQD-COM-003;DES-PNP;DES-PROXY-SIMPLE | E16: VCF-EDGE-REQD-PAT-009 | F16: PAT-009 is edge/latency-triggered; keep COM-003 as TechDocs deploy rule. | G16: https://techdocs.broadcom.com/us/en/vmware-cis/vcf/vcf-9-0-and-later/9-1/design/vmware-cloud-foundation-concepts/vcf-operations.html
A17: VCF Automation | B17: HA | C17: Medium | D17: VCF-AUTO-REQD-HA-001;DES-PNP | E17: VCF-AUTO-REQD-CFG-001;VCF-AUTO-REQD-CFG-002;VCF-AUTO-REQD-CFG-003;VCF-AUTO-REQD-CFG-006;VCF-AUTO-REQD-CFG-009;VCF-AUTO-REQD-CFG-010 | F17: CFG-002 is HA-only ‚Äî change Trigger from ALWAYS ‚Üí availabilityModel=HA. CFG-009 Large is production HA bias. | G17: https://techdocs.broadcom.com/us/en/vmware-cis/vcf/vcf-9-0-and-later/9-1/design/design-library/vcf-automation-deployment-models-9-x/vcf-automation-high-availability-deployment-model.html
A18: VCF Automation | B18: HA | C18: Large | D18: VCF-AUTO-REQD-HA-001;DES-PNP | E18: VCF-AUTO-REQD-CFG-001;VCF-AUTO-REQD-CFG-002;VCF-AUTO-REQD-CFG-003;VCF-AUTO-REQD-CFG-006;VCF-AUTO-REQD-CFG-009;VCF-AUTO-REQD-CFG-010 | F18: CFG-002 is HA-only ‚Äî change Trigger from ALWAYS ‚Üí availabilityModel=HA. CFG-009 Large is production HA bias. | G18: https://techdocs.broadcom.com/us/en/vmware-cis/vcf/vcf-9-0-and-later/9-1/design/design-library/vcf-automation-deployment-models-9-x/vcf-automation-high-availability-deployment-model.html
A19: VCF Automation | B19: Simple | C19: Small | D19: VCF-AUTO-REQD-SIM-001;VCF-AUTO-REQD-SIM-002;DES-PNP | E19: VCF-AUTO-REQD-CFG-001;VCF-AUTO-REQD-CFG-003;VCF-AUTO-REQD-CFG-004;VCF-AUTO-REQD-CFG-010 | F19: CFG-002 is HA-only ‚Äî change Trigger from ALWAYS ‚Üí availabilityModel=HA. CFG-009 Large is production HA bias. | G19: https://techdocs.broadcom.com/us/en/vmware-cis/vcf/vcf-9-0-and-later/9-1/design/design-library/vcf-automation-deployment-models-9-x/vcf-automation-simple-deployment-model.html
A20: VCF Operations | B20: HA | C20: Medium | D20: VCF-OPS-REQD-COM-001;DES-PNP;DES-FLEET-HA | E20: VCF-OPS-REQD-CFG-001;VCF-OPS-REQD-CFG-002;VCF-OPS-REQD-CFG-003;VCF-OPS-REQD-CFG-004;VCF-OPS-REQD-CFG-005;VCF-OPS-REQD-CFG-006;VCF-OPS-REQD-CFG-007;VCF-OPS-REQD-CFG-008 | F20: Add Ops SIM TechDocs ID; map HA to existing OPS CFG sizing/placement IDs. | G20: https://techdocs.broadcom.com/us/en/vmware-cis/vcf/vcf-9-0-and-later/9-1/design/vmware-cloud-foundation-concepts/vcf-operations.html
A21: VCF Operations | B21: HA | C21: Large | D21: VCF-OPS-REQD-COM-001;DES-PNP;DES-FLEET-HA | E21: VCF-OPS-REQD-CFG-001;VCF-OPS-REQD-CFG-002;VCF-OPS-REQD-CFG-003;VCF-OPS-REQD-CFG-004;VCF-OPS-REQD-CFG-005;VCF-OPS-REQD-CFG-006;VCF-OPS-REQD-CFG-007;VCF-OPS-REQD-CFG-008 | F21: Add Ops SIM TechDocs ID; map HA to existing OPS CFG sizing/placement IDs. | G21: https://techdocs.broadcom.com/us/en/vmware-cis/vcf/vcf-9-0-and-later/9-1/design/vmware-cloud-foundation-concepts/vcf-operations.html
A22: VCF Operations | B22: Simple | C22: Small | D22: VCF-OPS-REQD-COM-001;DES-PNP;VCF-OPS-REQD-SIM-001;DES-FLEET-SIMPLE | E22: VCF-OPS-REQD-CFG-001;VCF-OPS-REQD-CFG-002;VCF-OPS-REQD-CFG-003;VCF-OPS-REQD-CFG-004 | F22: Add Ops SIM TechDocs ID; map HA to existing OPS CFG sizing/placement IDs. | G22: https://techdocs.broadcom.com/us/en/vmware-cis/vcf/vcf-9-0-and-later/9-1/design/design-blueprints-for/infrastructure-modernization/vcf-fleet-in-a-single-site-with-minimal-footprint-blueprint/management-domain-design-selections/operations-layer/simple-vcf-operations-model.html
A23: Management Domain NSX Edges | B23: HA | C23: Small | D23: DES-PNP;DES-FLEET-HA;DES-OPTIONAL-DAYN | F23: No Funnel bridge yet ‚Äî keep DES-PNP / Fleet fallback; extend bridge as needed. | G23: https://techdocs.broadcom.com/us/en/vmware-cis/vcf/vcf-9-0-and-later/9-1/design/vmware-cloud-foundation-concepts/vcf-fleet-sizing-models-9-x.html
A24: Management Domain NSX Edges | B24: HA | C24: Medium | D24: DES-PNP;DES-FLEET-HA;DES-OPTIONAL-DAYN | F24: No Funnel bridge yet ‚Äî keep DES-PNP / Fleet fallback; extend bridge as needed. | G24: https://techdocs.broadcom.com/us/en/vmware-cis/vcf/vcf-9-0-and-later/9-1/design/vmware-cloud-foundation-concepts/vcf-fleet-sizing-models-9-x.html
A25: Management Domain NSX Edges | B25: HA | C25: Large | D25: DES-PNP;DES-FLEET-HA;DES-OPTIONAL-DAYN | F25: No Funnel bridge yet ‚Äî keep DES-PNP / Fleet fallback; extend bridge as needed. | G25: https://techdocs.broadcom.com/us/en/vmware-cis/vcf/vcf-9-0-and-later/9-1/design/vmware-cloud-foundation-concepts/vcf-fleet-sizing-models-9-x.html
A26: Management Domain NSX Edges | B26: HA | C26: X-Large | D26: DES-PNP;DES-FLEET-HA;DES-OPTIONAL-DAYN | F26: No Funnel bridge yet ‚Äî keep DES-PNP / Fleet fallback; extend bridge as needed. | G26: https://techdocs.broadcom.com/us/en/vmware-cis/vcf/vcf-9-0-and-later/9-1/design/vmware-cloud-foundation-concepts/vcf-fleet-sizing-models-9-x.html
